<?xml version="1.0"?>

<robot name="m0617" xmlns:xacro="http://www.ros.org/wiki/xacro">
	<xacro:include filename="$(find dsr_description)/config/macro.gazebo.xacro" />
	<xacro:include filename="$(find dsr_description)/config/macro.transmission.xacro" />
	<xacro:include filename="$(find dsr_description)/config/macro.materials.xacro" />
	<xacro:macro name="m0617" params="namespace">
		<xacro:dsr_materials />
		<link name="base_0">
			<inertial>
				<mass value="4.12"/>
				<origin xyz="-3.4e-05   -0.004815    0.048482"/>
				<inertia ixx="0.020415" ixy="-3.9311e-06" ixz="2.3764e-06" iyy="0.014927"
					iyz="-0.00051388"
					izz="0.023376"/>
			</inertial>
			<visual>
				<origin rpy="0 0 0" xyz="0 0 0" />
				<geometry>
					<mesh filename="package://dsr_description/meshes/m0617_white/MF0617_0_0.dae" scale="0.001 0.001 0.001" />
				</geometry>
			</visual>
		</link>
		<!-- joint 1 -->
		<joint name="joint1" type="revolute">
			<parent link="base_0" />
			<child link="link1" />
			<origin rpy="0 0 0" xyz="0 0 0.1525" />
			<axis xyz="0 0 1" />
			<limit effort="346" lower="-6.2832" upper="6.2832" velocity="1.7453"/>
			<dynamics friction="0" />
		</joint>
		<link name="link1">
			<inertial>
				<mass value="7.8"/>
				<origin xyz="0.000119      0.0428   -0.006383"/>
				<inertia ixx="0.047267" ixy="4.1409e-05" ixz="-5.3877e-05" iyy="0.03119"
					iyz="-0.0019953"
					izz="0.047021"/>
			</inertial>
            <collision>
                <geometry>
                    <cylinder radius="0.1" length="0.2"/>
                </geometry>
            </collision>
			<visual>
				<origin rpy="0 0 0" xyz="0 0 0" />
				<geometry>
					<mesh filename="package://dsr_description/meshes/m0617_white/MF0617_1_0.dae" scale="0.001 0.001 0.001" />
				</geometry>
			</visual>
		</link>
		<!-- joint2 -->
		<joint name="joint2" type="revolute">
			<parent link="link1" />
			<child link="link2" />
			<origin rpy="0 -1.571 -1.571" xyz="0 0.0345 0" />
			<axis xyz="0 0 1" />
			<limit effort="346" lower="-6.2832" upper="6.2832" velocity="1.7453"/>
			<dynamics friction="0" />
		</joint>
		<link name="link2">
			<inertial>
				<mass value="11.55"/>
				<origin xyz="0.35752      -5e-05      0.1582"/>
				<inertia ixx="0.039245" ixy="-0.00050916" ixz="-0.0099927" iyy="1.6244" iyz="4.4298e-05"
					izz="1.626"/>
			</inertial>
            <collision>
                <origin rpy="0 -1.571 0" xyz="0.45 0 0.1525" />
                <geometry>
                    <cylinder radius="0.08" length="0.9"/>
                </geometry>
            </collision>
			<visual>
				<origin rpy="0 0 0" xyz="0 0 0" />
				<geometry>
					<mesh filename="package://dsr_description/meshes/m0617_white/MF0617_2_0.dae" scale="0.001 0.001 0.001" />
				</geometry>
			</visual>
			<visual>
				<origin rpy="0 0 0" xyz="0 0 0" />
				<geometry>
					<mesh filename="package://dsr_description/meshes/m0617_white/MF0617_2_1.dae" scale="0.001 0.001 0.001" />
				</geometry>
			</visual>
			<visual>
				<origin rpy="0 0 0" xyz="0 0 0" />
				<geometry>
					<mesh filename="package://dsr_description/meshes/m0617_white/MF0617_2_2.dae" scale="0.001 0.001 0.001" />
				</geometry>
			</visual>
		</link>
		<!-- joint3 -->
		<joint name="joint3" type="revolute">
			<parent link="link2" />
			<child link="link3" />
			<origin rpy="0 0 1.571" xyz="0.845 0 0" />
			<axis xyz="0 0 1" />
			<limit effort="163" lower="-2.8798" upper="2.8798" velocity="2.618"/>
			<dynamics friction="0" />
		</joint>
		<link name="link3">
			<inertial>
				<mass value="3.68"/>
				<origin xyz="-1.5e-05   -0.006702    0.044608"/>
				<inertia ixx="0.020579" ixy="1.0111e-05" ixz="-6.784e-07" iyy="0.019181"
					iyz="-0.0009947"
					izz="0.014379"/>
			</inertial>
			<visual>
				<origin rpy="0 0 0" xyz="0 0 0" />
				<geometry>
					<mesh filename="package://dsr_description/meshes/m0617_white/MF0617_3_0.dae" scale="0.001 0.001 0.001" />
				</geometry>
			</visual>
		</link>
		<!-- joint4 -->
		<joint name="joint4" type="revolute">
			<parent link="link3" />
			<child link="link4" />
			<origin rpy="1.571 0 0" xyz="0 -0.734 0" />
			<axis xyz="0 0 1" />
			<limit effort="50" lower="-6.2832" upper="6.2832" velocity="3.927"/>
			<dynamics friction="0" />
		</joint>
		<link name="link4">
			<inertial>
				<mass value="4.28"/>
				<origin xyz="5.7e-05    0.091288    -0.25319"/>
				<inertia ixx="0.35652" ixy="-1.8897e-05" ixz="-4.9971e-05" iyy="0.33627" iyz="-0.076995"
					izz="0.029844"/>
			</inertial>
            <collision>
                <origin rpy="-0.32 0 0" xyz="0 0.07 -0.32" />
                <geometry>
                    <cylinder radius="0.07" length="0.5"/>
                </geometry>
            </collision>
			<visual>
				<origin rpy="0 0 0" xyz="0 0 0" />
				<geometry>
					<mesh filename="package://dsr_description/meshes/m0617_white/MF0617_4_0.dae" scale="0.001 0.001 0.001" />
				</geometry>
			</visual>
			<visual>
				<origin rpy="0 0 0" xyz="0 0 0" />
				<geometry>
					<mesh filename="package://dsr_description/meshes/m0617_white/MF0617_4_1.dae" scale="0.001 0.001 0.001" />
				</geometry>
			</visual>
		</link>
		<!-- joint5 -->
		<joint name="joint5" type="revolute">
			<parent link="link4" />
			<child link="link5" />
			<origin rpy="-1.571 0 0" xyz="0 0 0" />
			<axis xyz="0 0 1" />
			<limit effort="50" lower="-6.2832" upper="6.2832" velocity="3.927"/>
			<dynamics friction="0" />
		</joint>
		<link name="link5">
			<inertial>
				<mass value="2.8"/>
         	<origin xyz="-0.000273    0.003651     0.032087"/>
				<inertia ixx="0.012016" ixy="2.1647e-05" ixz="-4.85e-06" iyy="0.013232" iyz="0.00042654"
					izz="0.010423"/>
			</inertial>
            <collision>
                <origin rpy="1.571 0 0" xyz="0 0 0" />
                <geometry>
                    <cylinder radius="0.08" length="0.15"/>
                </geometry>
            </collision>
			<visual>
				<origin rpy="0 0 0" xyz="0 0 0" />
				<geometry>
					<mesh filename="package://dsr_description/meshes/m0617_white/MF0617_5_0.dae" scale="0.001 0.001 0.001" />
				</geometry>
			</visual>
		</link>
		<!-- joint6 -->
		<joint name="joint6" type="revolute">
			<parent link="link5" />
			<child link="link6" />
			<origin rpy="1.571 0 0" xyz="0 -0.121 0" />
			<axis xyz="0 0 1" />
			<limit effort="50" lower="-6.2832" upper="6.2832" velocity="3.927"/>
			<dynamics friction="0" />
		</joint>
		<link name="link6">
			<inertial>
				<mass value="1.16"/>
				<origin xyz="-0.000292       7e-06     -0.0539"/>
				<inertia ixx="0.0086448" ixy="3.5791e-06" ixz="5.1469e-06" iyy="0.0045613"
					iyz="5.8483e-06"
					izz="0.0086768"/>
			</inertial>
			<visual>
				<origin rpy="0 0 0" xyz="0 0 0" />
				<geometry>
					<mesh filename="package://dsr_description/meshes/m0617_white/MF0617_6_0.dae" scale="0.001 0.001 0.001" />
				</geometry>
			</visual>
		</link>
		<xacro:dsr_transmission />
		<xacro:dsr_gazebo namespace="${namespace}" />
	</xacro:macro>
</robot>
