<?xml version="1.0"?>

<robot name="h2515" xmlns:xacro="http://www.ros.org/wiki/xacro">
	<xacro:include filename="$(find dsr_description)/config/macro.gazebo.xacro" />
	<xacro:include filename="$(find dsr_description)/config/macro.transmission.xacro" />
	<xacro:include filename="$(find dsr_description)/config/macro.materials.xacro" />
	<xacro:macro name="h2515" params="namespace">
		<xacro:dsr_materials />
		<link name="base_0">
			<inertial>
				<mass value="8.537"/>
				<origin xyz="-1.8e-05   -0.002377    0.095608"/>
				<inertia ixx="0.078238" ixy="3.026e-05" ixz="1.7626e-05" iyy="0.077909"
					iyz="-0.00099645"
					izz="0.068138"/>
				</inertial>
				<visual>
					<origin rpy="0 0 0" xyz="0 0 0" />
					<geometry>
						<mesh filename="package://dsr_description/meshes/h2515_blue/H2515_0_0.dae" scale="0.001 0.001 0.001" />
					</geometry>
				</visual>
			</link>
		<!-- joint 1 -->
		<joint name="joint1" type="revolute">
			<parent link="base_0" />
			<child link="link1" />
			<origin rpy="0 0 0" xyz="0 0 0.3443" />
			<axis xyz="0 0 1" />
			<limit effort="372" lower="-6.2832" upper="6.2832" velocity="1.7453"/>
			<dynamics friction="0" />
		</joint>
		<link name="link1">
			<inertial>
				<mass value="20.253"/>
				<origin xyz="-5.3e-05     0.11854   -0.059979"/>
				<inertia ixx="0.52872" ixy="-5.7923e-05" ixz="-7.341e-06" iyy="0.27999" iyz="-0.149"
					izz="0.34741"/>
			</inertial>
            <collision>
                <geometry>
                    <cylinder radius="0.1" length="0.2"/>
                </geometry>
            </collision>
			<visual>
				<origin rpy="0 0 0" xyz="0 0 0" />
				<geometry>
					<mesh filename="package://dsr_description/meshes/h2515_white/H2515_1_0.dae" scale="0.001 0.001 0.001" />
				</geometry>
			</visual>
		</link>
		<!-- joint2 -->
		<joint name="joint2" type="revolute">
			<parent link="link1" />
			<child link="link2" />
			<origin rpy="0 -1.571 -1.571" xyz="0 0.0099 0" />
			<axis xyz="0 0 1" />
			<limit effort="372" lower="-2.1817" upper="2.1817" velocity="1.3963"/>
			<dynamics friction="0" />
		</joint>
		<link name="link2">
			<inertial>
				<mass value="28.111"/>
				<origin xyz="0.35729    -2.4e-05     0.22527"/>				
				<inertia ixx="0.15204" ixy="-0.00010891" ixz="0.107" iyy="2.5113" iyz="-5.2156e-05"
					izz="2.4697"/>
			</inertial>
            <collision>
                <origin rpy="0 -1.571 0" xyz="0.3 0 0.1525" />
                <geometry>
                    <cylinder radius="0.08" length="0.75"/>
                </geometry>
            </collision>
			<visual>
				<origin rpy="0 0 0" xyz="0 0 0" />
				<geometry>
					<mesh filename="package://dsr_description/meshes/h2515_white/H2515_2_0.dae" scale="0.001 0.001 0.001" />
				</geometry>
			</visual>
			<visual>
				<origin rpy="0 0 0" xyz="0 0 0" />
				<geometry>
					<mesh filename="package://dsr_description/meshes/h2515_white/H2515_2_1.dae" scale="0.001 0.001 0.001" />
				</geometry>
			</visual>
			<visual>
				<origin rpy="0 0 0" xyz="0 0 0" />
				<geometry>
					<mesh filename="package://dsr_description/meshes/h2515_white/H2515_2_2.dae" scale="0.001 0.001 0.001" />
				</geometry>
			</visual>
		</link>
		<!-- joint3 -->
		<joint name="joint3" type="revolute">
			<parent link="link2" />
			<child link="link3" />
			<origin rpy="0 0 1.571" xyz="0.7595 0 0" />
			<axis xyz="0 0 1" />
			<limit effort="372" lower="-2.7925" upper="2.7925" velocity="1.7453"/>
			<dynamics friction="0" />
		</joint>
		<link name="link3">
			<inertial>
				<mass value="6.421"/>
				<origin xyz="-6.5e-05  -0.0074124    0.049527"/>
				<inertia ixx="0.042338" ixy="2.9627e-05" ixz="-1.1919e-05" iyy="0.039418"
					iyz="-0.0029936"
					izz="0.028103"/>
			</inertial>
            <visual>
				<origin rpy="0 0 0" xyz="0 0 0" />
				<geometry>
					<mesh filename="package://dsr_description/meshes/h2515_white/H2515_3_0.dae" scale="0.001 0.001 0.001" />
				</geometry>
			</visual>
		</link>
		<!-- joint4 -->
		<joint name="joint4" type="revolute">
			<parent link="link3" />
			<child link="link4" />
			<origin rpy="1.571 0 0" xyz="0 -0.6195 0" />
			<axis xyz="0 0 1" />
			<limit effort="163" lower="-6.2832" upper="6.2832" velocity="3.1416"/>
			<dynamics friction="0" />
		</joint>
		<link name="link4">
			<inertial>
				<mass value="7.295"/>
				<origin xyz="7.9e-05     0.13068    -0.17947"/>
				<inertia ixx="0.41598" ixy="-6.9414e-05" ixz="-0.00010777" iyy="0.36426" iyz="-0.12499"
					izz="0.075756"/>
			</inertial>
            <collision>
                <origin rpy="-0.55 0 0" xyz="0 0.07 -0.3" />
                <geometry>
                    <cylinder radius="0.07" length="0.4"/>
                </geometry>
            </collision>
			<visual>
				<origin rpy="0 0 0" xyz="0 0 0" />
				<geometry>
					<mesh filename="package://dsr_description/meshes/h2515_white/H2515_4_0.dae" scale="0.001 0.001 0.001" />
				</geometry>
			</visual>
			<visual>
				<origin rpy="0 0 0" xyz="0 0 0" />
				<geometry>
					<mesh filename="package://dsr_description/meshes/h2515_white/H2515_4_1.dae" scale="0.001 0.001 0.001" />
				</geometry>
			</visual>
		</link>
		<!-- joint5 -->
		<joint name="joint5" type="revolute">
			<parent link="link4" />
			<child link="link5" />
			<origin rpy="-1.571 0 0" xyz="0 0 0" />
			<axis xyz="0 0 1" />
			<limit effort="96" lower="-6.2832" upper="6.2832" velocity="3.1416"/>
			<dynamics friction="0" />
		</joint>
		<link name="link5">
			<inertial>
				<mass value="4.099"/>
				<origin xyz="-6.1e-05   -0.000589    0.048788"/>
				<inertia ixx="0.024784" ixy="2.2652e-05" ixz="-5.8056e-06" iyy="0.024229"
					iyz="5.8109e-05"
					izz="0.012218"/>
			</inertial>
            <collision>
                <origin rpy="1.571 0 0" xyz="0 0 0" />
                <geometry>
                    <cylinder radius="0.08" length="0.15"/>
                </geometry>
            </collision>
			<visual>
				<origin rpy="0 0 0" xyz="0 0 0" />
				<geometry>
					<mesh filename="package://dsr_description/meshes/h2515_white/H2515_5_0.dae" scale="0.001 0.001 0.001" />
				</geometry>
			</visual>
		</link>
		<!-- joint6 -->
		<joint name="joint6" type="revolute">
			<parent link="link5" />
			<child link="link6" />
			<origin rpy="1.571 0 0" xyz="0 -0.121 0" />
			<axis xyz="0 0 1" />
			<limit effort="50" lower="-6.2832" upper="6.2832" velocity="3.927"/>
			<dynamics friction="0" />
		</joint>
		<link name="link6">
			<inertial>
				<mass value="0.897"/>
				<origin xyz="-3.3e-05     1.2e-05   -0.049444"/>
				<inertia ixx="0.0081209" ixy="7.9444e-06" ixz="7.3951e-06" iyy="0.0071981"
					iyz="4.2669e-06"
					izz="0.0079983"/>
			</inertial>
			<visual>
				<origin rpy="0 0 0" xyz="0 0 0" />
				<geometry>
					<mesh filename="package://dsr_description/meshes/h2515_white/H2515_6_0.dae" scale="0.001 0.001 0.001" />
				</geometry>
			</visual>
		</link>
		<xacro:dsr_transmission />
		<xacro:dsr_gazebo namespace="${namespace}" />
	</xacro:macro>
</robot>
