<?xml version="1.0"?>

<robot name="m1509" xmlns:xacro="http://www.ros.org/wiki/xacro">
	<xacro:include filename="$(find dsr_description)/config/macro.gazebo.xacro" />
	<xacro:include filename="$(find dsr_description)/config/macro.transmission.xacro" />
	<xacro:include filename="$(find dsr_description)/config/macro.materials.xacro" />
	<xacro:macro name="m1509" params="namespace">
		<xacro:dsr_materials />
		<link name="base_0">
			<inertial>
				<mass value="4.12"/>
				<origin xyz="-3.4e-05   -0.004815    0.048482"/>
				<inertia ixx="0.016805" ixy="-5.5036e-06" ixz="2.7445e-06" iyy="0.016834"
					iyz="-0.00051575"
					izz="0.022647"/>
			</inertial>
			<visual>
				<origin rpy="0 0 0" xyz="0 0 0" />
				<geometry>
					<mesh filename="package://dsr_description/meshes/m1509_white/MF1509_0_0.dae" scale="0.001 0.001 0.001" />
				</geometry>
			</visual>
		</link>
		<!-- joint 1 -->
		<joint name="joint1" type="revolute">
			<parent link="base_0" />
			<child link="link1" />
			<origin rpy="0 0 0" xyz="0 0 0.1525" />
			<axis xyz="0 0 1" />
			<limit effort="346" lower="-6.2832" upper="6.2832" velocity="2.618"/>
			<dynamics friction="0" />
		</joint>
		<link name="link1">
			<inertial>
				<mass value="7.8"/>
				<origin xyz="0.000119      0.0428   -0.006382"/>
				<inertia ixx="0.047481" ixy="4.2706e-05" ixz="-5.3678e-05" iyy="0.030766"
					iyz="-0.0019938"
					izz="0.047461"/>
			</inertial>
            <collision>
                <geometry>
                    <cylinder radius="0.08" length="0.2"/>
                </geometry>
            </collision>
			<visual>
				<origin rpy="0 0 0" xyz="0 0 0" />
				<geometry>
					<mesh filename="package://dsr_description/meshes/m1509_white/MF1509_1_0.dae" scale="0.001 0.001 0.001" />
				</geometry>
			</visual>
		</link>
		<!-- joint2 -->
		<joint name="joint2" type="revolute">
			<parent link="link1" />
			<child link="link2" />
			<origin rpy="0 -1.571 -1.571" xyz="0 0.0345 0" />
			<axis xyz="0 0 1" />
			<limit effort="346" lower="-6.2832" upper="6.2832" velocity="2.618"/>
			<dynamics friction="0" />
		</joint>
		<link name="link2">
			<inertial>
				<mass value="10.06"/>
				<origin xyz="0.17059    -5.8e-05     0.15734"/>
				<inertia ixx="0.037059" ixy="-0.00023967" ixz="-0.0049921" iyy="0.3701" iyz="4.2201e-05"
					izz="0.36866"/>
			</inertial>
            <collision>
                <origin rpy="0 -1.571 0" xyz="0.2 0 0.1525" />
                <geometry>
                    <cylinder radius="0.08" length="0.5"/>
                </geometry>
            </collision>
			<visual>
				<origin rpy="0 0 0" xyz="0 0 0" />
				<geometry>
					<mesh filename="package://dsr_description/meshes/m1509_white/MF1509_2_0.dae" scale="0.001 0.001 0.001" />
				</geometry>
			</visual>
			<visual>
				<origin rpy="0 0 0" xyz="0 0 0" />
				<geometry>
					<mesh filename="package://dsr_description/meshes/m1509_white/MF1509_2_1.dae" scale="0.001 0.001 0.001" />
				</geometry>
			</visual>
			<visual>
				<origin rpy="0 0 0" xyz="0 0 0" />
				<geometry>
					<mesh filename="package://dsr_description/meshes/m1509_white/MF1509_2_2.dae" scale="0.001 0.001 0.001" />
				</geometry>
			</visual>
		</link>
		<!-- joint3 -->
		<joint name="joint3" type="revolute">
			<parent link="link2" />
			<child link="link3" />
			<origin rpy="0 0 1.571" xyz="0.411 0 0" />
			<axis xyz="0 0 1" />
			<limit effort="163" lower="-2.618" upper="2.618" velocity="3.1416"/>
			<dynamics friction="0" />
		</joint>
		<link name="link3">
			<inertial>
				<mass value="3.68"/>
				<origin xyz="-1.5e-05    -0.00671    0.044632"/>
				<inertia ixx="0.019496" ixy="1.0207e-05" ixz="-4.6541e-06" iyy="0.015303"
					iyz="-0.00099648"
					izz="0.011095"/>
			</inertial>
			<visual>
				<origin rpy="0 0 0" xyz="0 0 0" />
				<geometry>
					<mesh filename="package://dsr_description/meshes/m1509_white/MF1509_3_0.dae" scale="0.001 0.001 0.001" />
				</geometry>
			</visual>
		</link>
		<!-- joint4 -->
		<joint name="joint4" type="revolute">
			<parent link="link3" />
			<child link="link4" />
			<origin rpy="1.571 0 0" xyz="0 -0.368 0" />
			<axis xyz="0 0 1" />
			<limit effort="50" lower="-6.2832" upper="6.2832" velocity="3.927"/>
			<dynamics friction="0" />
		</joint>
		<link name="link4">
			<inertial>
				<mass value="3.59"/>
				<origin xyz="3.9e-05     0.09731     -0.1096"/>
				<inertia ixx="0.082012" ixy="-5.6458e-06" ixz="-8.1419e-06" iyy="0.06358"
					iyz="-0.028995"
					izz="0.025281"/>
			</inertial>
            <collision>
                <origin rpy="-0.55 0 0" xyz="0 0.075 -0.16" />
                <geometry>
                    <cylinder radius="0.05" length="0.4"/>
                </geometry>
            </collision>
			<visual>
				<origin rpy="0 0 0" xyz="0 0 0" />
				<geometry>
					<mesh filename="package://dsr_description/meshes/m1509_white/MF1509_4_0.dae" scale="0.001 0.001 0.001" />
				</geometry>
			</visual>
			<visual>
				<origin rpy="0 0 0" xyz="0 0 0" />
				<geometry>
					<mesh filename="package://dsr_description/meshes/m1509_white/MF1509_4_1.dae" scale="0.001 0.001 0.001" />
				</geometry>
			</visual>
		</link>
		<!-- joint5 -->
		<joint name="joint5" type="revolute">
			<parent link="link4" />
			<child link="link5" />
			<origin rpy="-1.571 0 0" xyz="0 0 0" />
			<axis xyz="0 0 1" />
			<limit effort="50" lower="-6.2832" upper="6.2832" velocity="3.927"/>
			<dynamics friction="0" />
		</joint>
		<link name="link5">
			<inertial>
				<mass value="2.83"/>
				<origin xyz="-6.9e-05    0.003827    0.032006"/>
				<inertia ixx="0.016871" ixy="1.9694e-05" ixz="2.9684e-06" iyy="0.013767"
					iyz="0.00044631"
					izz="0.0097685"/>
			</inertial>
            <collision>
                <origin rpy="1.571 0 0" xyz="0 0 0" />
                <geometry>
                    <cylinder radius="0.06" length="0.15"/>
                </geometry>
            </collision>
			<visual>
				<origin rpy="0 0 0" xyz="0 0 0" />
				<geometry>
					<mesh filename="package://dsr_description/meshes/m1509_white/MF1509_5_0.dae" scale="0.001 0.001 0.001" />
				</geometry>
			</visual>
		</link>
		<!-- joint6 -->
		<joint name="joint6" type="revolute">
			<parent link="link5" />
			<child link="link6" />
			<origin rpy="1.571 0 0" xyz="0 -0.121 0" />
			<axis xyz="0 0 1" />
			<limit effort="50" lower="-6.2832" upper="6.2832" velocity="3.927"/>
			<dynamics friction="0" />
		</joint>
		<link name="link6">
			<inertial>
				<mass value="1.16"/>
				<origin xyz="-3.2e-05       8e-06     -0.0539"/>
				<inertia ixx="0.0048523" ixy="2.7941e-06" ixz="4.9172e-06" iyy="0.0047546"
					iyz="3.1535e-06"
					izz="0.0071373"/>
			</inertial>
			<visual>
				<origin rpy="0 0 0" xyz="0 0 0" />
				<geometry>
					<mesh filename="package://dsr_description/meshes/m1509_white/MF1509_6_0.dae" scale="0.001 0.001 0.001" />
				</geometry>
			</visual>
		</link>
		<xacro:dsr_transmission />
		<xacro:dsr_gazebo namespace="${namespace}" />
	</xacro:macro>
</robot>
