<?xml version="1.0"?>

<robot name="h2017" xmlns:xacro="http://www.ros.org/wiki/xacro">
	<xacro:include filename="$(find dsr_description)/config/macro.gazebo.xacro" />
	<xacro:include filename="$(find dsr_description)/config/macro.transmission.xacro" />
	<xacro:include filename="$(find dsr_description)/config/macro.materials.xacro" />
	<xacro:macro name="h2017" params="namespace">
		<xacro:dsr_materials />
		<link name="base_0">
			<inertial>
				<mass value="8.537"/>
				<origin xyz="1.8e-05   -0.002377    0.095608"/>
				<inertia ixx="0.079499" ixy="2.9382e-05" ixz="1.7529e-05" iyy="0.076993"
					iyz="-0.0009938"
					izz="0.067833"/>
			</inertial>
			<visual>
				<origin rpy="0 0 0" xyz="0 0 0" />
				<geometry>
					<mesh filename="package://dsr_description/meshes/h2017_white/H2017_0_0.dae" scale="0.001 0.001 0.001" />
				</geometry>
			</visual>
		</link>
		<!-- joint 1 -->
		<joint name="joint1" type="revolute">
			<parent link="base_0" />
			<child link="link1" />
			<origin rpy="0 0 0" xyz="0 0 0.3443" />
			<axis xyz="0 0 1" />
			<limit effort="372" lower="-6.2832" upper="6.2832" velocity="1.7453"/>
			<dynamics friction="0" />
		</joint>
		<link name="link1">
			<inertial>
				<mass value="20.253"/>
				<origin xyz="-5e-05     0.11854   -0.059979"/>
				<inertia ixx="0.5323" ixy="-6.2817e-05" ixz="-7.5664e-06" iyy="0.2807" iyz="-0.14899"
					izz="0.34857"/>
			</inertial>
            <collision>
                <geometry>
                    <cylinder radius="0.1" length="0.2"/>
                </geometry>
            </collision>
			<visual>
				<origin rpy="0 0 0" xyz="0 0 0" />
				<geometry>
					<mesh filename="package://dsr_description/meshes/h2017_white/H2017_1_0.dae" scale="0.001 0.001 0.001" />
				</geometry>
			</visual>
		</link>
		<!-- joint2 -->
		<joint name="joint2" type="revolute">
			<parent link="link1" />
			<child link="link2" />
			<origin rpy="0 -1.571 -1.571" xyz="0 0.0099 0" />
			<axis xyz="0 0 1" />
			<limit effort="372" lower="-2.1817" upper="2.1817" velocity="1.3963"/>
			<dynamics friction="0" />
		</joint>
		<link name="link2">
			<inertial>
				<mass value="28.536"/>
				<origin xyz="0.38055    -1.7e-05     0.22527"/>
				<inertia ixx="0.15388" ixy="-0.00022213" ixz="0.11801" iyy="3.0424" iyz="-5.3325e-05"
					izz="3.0015"/>
			</inertial>
            <collision>
                <origin rpy="0 -1.571 0" xyz="0.3 0 0.1525" />
                <geometry>
                    <cylinder radius="0.08" length="0.75"/>
                </geometry>
            </collision>
			<visual>
				<origin rpy="0 0 0" xyz="0 0 0" />
				<geometry>
					<mesh filename="package://dsr_description/meshes/h2017_white/H2017_2_0.dae" scale="0.001 0.001 0.001" />
				</geometry>
			</visual>
			<visual>
				<origin rpy="0 0 0" xyz="0 0 0" />
				<geometry>
					<mesh filename="package://dsr_description/meshes/h2017_white/H2017_2_1.dae" scale="0.001 0.001 0.001" />
				</geometry>
			</visual>
			<visual>
				<origin rpy="0 0 0" xyz="0 0 0" />
				<geometry>
					<mesh filename="package://dsr_description/meshes/h2017_white/H2017_2_2.dae" scale="0.001 0.001 0.001" />
				</geometry>
			</visual>
		</link>
		<!-- joint3 -->
		<joint name="joint3" type="revolute">
			<parent link="link2" />
			<child link="link3" />
			<origin rpy="0 0 1.571" xyz="0.845 0 0" />
			<axis xyz="0 0 1" />
			<limit effort="372" lower="-2.7925" upper="2.7925" velocity="1.7453"/>
			<dynamics friction="0" />
		</joint>
		<link name="link3">
			<inertial>
				<mass value="6.421"/>
				<origin xyz="-5.9e-05   -0.008325    0.049527"/>
				<inertia ixx="0.04463" ixy="3.0207e-05" ixz="-1.0987e-05" iyy="0.041031"
					iyz="-0.0029929"
					izz="0.028983"/>
			</inertial>
            <visual>
				<origin rpy="0 0 0" xyz="0 0 0" />
				<geometry>
					<mesh filename="package://dsr_description/meshes/h2017_white/H2017_3_0.dae" scale="0.001 0.001 0.001" />
				</geometry>
			</visual>
		</link>
		<!-- joint4 -->
		<joint name="joint4" type="revolute">
			<parent link="link3" />
			<child link="link4" />
			<origin rpy="1.571 0 0" xyz="0 -0.734 0" />
			<axis xyz="0 0 1" />
			<limit effort="163" lower="-6.2832" upper="6.2832" velocity="3.1416"/>
			<dynamics friction="0" />
		</joint>
		<link name="link4">
			<inertial>
				<mass value="7.59"/>
				<origin xyz="7.7e-05     0.12896    -0.22056"/>
				<inertia ixx="0.60329" ixy="-6.8213e-05" ixz="-0.00013439" iyy="0.54966" iyz="-0.159"
					izz="0.078126"/>
			</inertial>
            <collision>
                <origin rpy="-0.55 0 0" xyz="0 0.07 -0.3" />
                <geometry>
                    <cylinder radius="0.07" length="0.4"/>
                </geometry>
            </collision>
			<visual>
				<origin rpy="0 0 0" xyz="0 0 0" />
				<geometry>
					<mesh filename="package://dsr_description/meshes/h2017_white/H2017_4_0.dae" scale="0.001 0.001 0.001" />
				</geometry>
			</visual>
			<visual>
				<origin rpy="0 0 0" xyz="0 0 0" />
				<geometry>
					<mesh filename="package://dsr_description/meshes/h2017_white/H2017_4_1.dae" scale="0.001 0.001 0.001" />
				</geometry>
			</visual>
		</link>
		<!-- joint5 -->
		<joint name="joint5" type="revolute">
			<parent link="link4" />
			<child link="link5" />
			<origin rpy="-1.571 0 0" xyz="0 0 0" />
			<axis xyz="0 0 1" />
			<limit effort="96" lower="-6.2832" upper="6.2832" velocity="3.1416"/>
			<dynamics friction="0" />
		</joint>
		<link name="link5">
			<inertial>
				<mass value="4.099"/>
				<origin xyz="-6.1e-05   -0.000589    0.048812"/>				
				<inertia ixx="0.021303" ixy="2.545e-05" ixz="-4.3439e-06" iyy="0.023894"
					iyz="6.0426e-05"
					izz="0.014587"/>
			</inertial>
            <collision>
                <origin rpy="1.571 0 0" xyz="0 0 0" />
                <geometry>
                    <cylinder radius="0.08" length="0.15"/>
                </geometry>
            </collision>
			<visual>
				<origin rpy="0 0 0" xyz="0 0 0" />
				<geometry>
					<mesh filename="package://dsr_description/meshes/h2017_white/H2017_5_0.dae" scale="0.001 0.001 0.001" />
				</geometry>
			</visual>
		</link>
		<!-- joint6 -->
		<joint name="joint6" type="revolute">
			<parent link="link5" />
			<child link="link6" />
			<origin rpy="1.571 0 0" xyz="0 -0.121 0" />
			<axis xyz="0 0 1" />
			<limit effort="50" lower="-6.2832" upper="6.2832" velocity="3.927"/>
			<dynamics friction="0" />
		</joint>
		<link name="link6">
			<inertial>
				<mass value="0.897"/>
				<origin xyz="-3.3e-05     3.6e-05   -0.049443"/>
				<inertia ixx="0.0086582" ixy="7.8198e-06" ixz="2.2495e-06" iyy="0.0068184"
					iyz="5.6115e-06"
					izz="0.0080729"/>
			</inertial>
			<visual>
				<origin rpy="0 0 0" xyz="0 0 0" />
				<geometry>
					<mesh filename="package://dsr_description/meshes/h2017_white/H2017_6_0.dae" scale="0.001 0.001 0.001" />
				</geometry>
			</visual>
		</link>
		<xacro:dsr_transmission />
		<xacro:dsr_gazebo namespace="${namespace}" />
	</xacro:macro>
</robot>
