<sdf version='1.6'>
  <world name='default'>
    <light name='sun' type='directional'>
      <cast_shadows>1</cast_shadows>
      <pose frame=''>0 0 10 0 -0 0</pose>
      <diffuse>0.8 0.8 0.8 1</diffuse>
      <specular>0.1 0.1 0.1 1</specular>
      <attenuation>
        <range>1000</range>
        <constant>0.9</constant>
        <linear>0.01</linear>
        <quadratic>0.001</quadratic>
      </attenuation>
      <direction>-0.5 0.5 -1</direction>
    </light>
    <model name='ground_plane'>
      <static>1</static>
      <link name='link'>
        <collision name='collision'>
          <geometry>
            <plane>
              <normal>0 0 1</normal>
              <size>100 100</size>
            </plane>
          </geometry>
          <surface>
            <friction>
              <ode>
                <mu>100</mu>
                <mu2>50</mu2>
              </ode>
              <torsional>
                <ode/>
              </torsional>
            </friction>
            <contact>
              <ode/>
            </contact>
            <bounce/>
          </surface>
          <max_contacts>10</max_contacts>
        </collision>
        <visual name='visual'>
          <cast_shadows>0</cast_shadows>
          <geometry>
            <plane>
              <normal>0 0 1</normal>
              <size>100 100</size>
            </plane>
          </geometry>
          <material>
            <script>
              <uri>file://media/materials/scripts/gazebo.material</uri>
              <name>Gazebo/Grey</name>
            </script>
          </material>
        </visual>
        <self_collide>0</self_collide>
        <kinematic>0</kinematic>
        <gravity>1</gravity>
      </link>
    </model>
    <physics name='default_physics' default='0' type='ode'>
      <real_time_update_rate>1000</real_time_update_rate>
      <max_step_size>0.001</max_step_size>
      <real_time_factor>1</real_time_factor>
      <ode>
        <solver>
          <type>quick</type>
          <iters>150</iters>
          <precon_iters>0</precon_iters>
          <sor>1.4</sor>
          <use_dynamic_moi_rescaling>1</use_dynamic_moi_rescaling>
        </solver>
        <constraints>
          <cfm>1e-05</cfm>
          <erp>0.2</erp>
          <contact_max_correcting_vel>2000</contact_max_correcting_vel>
          <contact_surface_layer>0.01</contact_surface_layer>
        </constraints>
      </ode>
    </physics>
    <scene>
      <ambient>0.4 0.4 0.4 1</ambient>
      <background>0.7 0.7 0.7 1</background>
      <shadows>1</shadows>
    </scene>
    <gui fullscreen='0'>
      <camera name='user_camera'>
        <pose> 2.0 -2.0 1.2 0.0 0.275643 2.356190 </pose>
        <view_controller>orbit</view_controller>
        <projection_type>perspective</projection_type>
      </camera>
    </gui>
    <gravity>0 0 -9.8</gravity>
    <magnetic_field>6e-06 2.3e-05 -4.2e-05</magnetic_field>
    <atmosphere type='adiabatic'/>
    <spherical_coordinates>
      <surface_model>EARTH_WGS84</surface_model>
      <latitude_deg>0</latitude_deg>
      <longitude_deg>0</longitude_deg>
      <elevation>0</elevation>
      <heading_deg>0</heading_deg>
    </spherical_coordinates>
    <model name='m0609'>
      <link name='base_0'>
        <pose frame=''>0 0 0 0 -0 0</pose>
        <inertial>
          <pose frame=''>-1.2e-05 -6e-05 0.050723 0 -0 0</pose>
          <mass>3.722</mass>
          <inertia>
            <ixx>0.011</ixx>
            <ixy>-7.19e-06</ixy>
            <ixz>-1.94e-06</ixz>
            <iyy>0.011</iyy>
            <iyz>4.9e-06</iyz>
            <izz>0.014</izz>
          </inertia>
        </inertial>
        <visual name='base_0_visual'>
          <pose frame=''>0 0 0 0 -0 0</pose>
          <geometry>
            <mesh>
              <scale>1 1 1</scale>
              <uri>/home/dra/catkin_ws/src/doosan_robot_v003/dr_description/meshes/m0609/MF0609_0_0.stl</uri>
            </mesh>
          </geometry>
          <material>
            <script>
              <name>Gazebo/Grey</name>
              <uri>file://media/materials/scripts/gazebo.material</uri>
            </script>
          </material>
        </visual>
        <gravity>1</gravity>
        <velocity_decay/>
        <self_collide>0</self_collide>
        <kinematic>0</kinematic>
      </link>
      <joint name='world_fixed' type='revolute'>
        <child>base_0</child>
        <parent>world</parent>
        <axis>
          <limit>
            <lower>0</lower>
            <upper>0</upper>
          </limit>
          <dynamics>
            <damping>0</damping>
            <friction>0</friction>
            <spring_reference>0</spring_reference>
            <spring_stiffness>0</spring_stiffness>
          </dynamics>
          <use_parent_model_frame>1</use_parent_model_frame>
          <xyz>0 0 1</xyz>
        </axis>
      </joint>
      <link name='link1'>
        <pose frame=''>0 0 0.1525 0 -0 0</pose>
        <inertial>
          <pose frame=''>7e-05 0.044281 0.143327 0 -0 0</pose>
          <mass>7.446</mass>
          <inertia>
            <ixx>0.039</ixx>
            <ixy>2.1e-05</ixy>
            <ixz>-3.61e-05</ixz>
            <iyy>0.023</iyy>
            <iyz>-0.003</iyz>
            <izz>0.039</izz>
          </inertia>
        </inertial>
        <visual name='link1_visual'>
          <pose frame=''>0 0 0 0 -0 0</pose>
          <geometry>
            <mesh>
              <scale>1 1 1</scale>
              <uri>/home/dra/catkin_ws/src/doosan_robot_v003/dr_description/meshes/m0609/MF0609_1_0.stl</uri>
            </mesh>
          </geometry>
          <material>
            <script>
              <name>Gazebo/White</name>
              <uri>file://media/materials/scripts/gazebo.material</uri>
            </script>
          </material>
        </visual>
        <gravity>1</gravity>
        <velocity_decay/>
        <self_collide>0</self_collide>
        <kinematic>0</kinematic>
      </link>
      <joint name='joint1' type='revolute'>
        <child>link1</child>
        <parent>base_0</parent>
        <axis>
          <xyz>0 0 1</xyz>
          <limit>
            <lower>-6.283</lower>
            <upper>6.283</upper>
            <effort>3460</effort>
            <velocity>2.094</velocity>
          </limit>
          <dynamics>
            <damping>0</damping>
            <friction>0</friction>
            <spring_reference>0</spring_reference>
            <spring_stiffness>0</spring_stiffness>
          </dynamics>
          <use_parent_model_frame>1</use_parent_model_frame>
        </axis>
      </joint>
      <link name='link2'>
        <pose frame=''>0 0.0062 0.1525 3.14159 -1.57059 1.57059</pose>
        <inertial>
          <pose frame=''>-1.6e-05 0.189372 0.418558 0 -0 0</pose>
          <mass>10.569</mass>
          <inertia>
            <ixx>0.82</ixx>
            <ixy>1.19e-05</ixy>
            <ixz>-0.000263</ixz>
            <iyy>0.82</iyy>
            <iyz>-0.008</iyz>
            <izz>0.031</izz>
          </inertia>
        </inertial>
        <visual name='link2_visual'>
          <pose frame=''>0 0 0 0 -0 0</pose>
          <geometry>
            <mesh>
              <scale>1 1 1</scale>
              <uri>/home/dra/catkin_ws/src/doosan_robot_v003/dr_description/meshes/m0609/MF0609_2_0.stl</uri>
            </mesh>
          </geometry>
          <material>
            <script>
              <name>Gazebo/White</name>
              <uri>file://media/materials/scripts/gazebo.material</uri>
            </script>
          </material>
        </visual>
        <visual name='link2_visual_1'>
          <pose frame=''>0 0 0 0 -0 0</pose>
          <geometry>
            <mesh>
              <scale>1 1 1</scale>
              <uri>/home/dra/catkin_ws/src/doosan_robot_v003/dr_description/meshes/m0609/MF0609_2_1.stl</uri>
            </mesh>
          </geometry>
          <material>
            <script>
              <name>Gazebo/White</name>
              <uri>file://media/materials/scripts/gazebo.material</uri>
            </script>
          </material>
        </visual>
        <visual name='link2_visual_2'>
          <pose frame=''>0 0 0 0 -0 0</pose>
          <geometry>
            <mesh>
              <scale>1 1 1</scale>
              <uri>/home/dra/catkin_ws/src/doosan_robot_v003/dr_description/meshes/m0609/MF0609_2_2.stl</uri>
            </mesh>
          </geometry>
          <material>
            <script>
              <name>Gazebo/White</name>
              <uri>file://media/materials/scripts/gazebo.material</uri>
            </script>
          </material>
        </visual>
        <gravity>1</gravity>
        <velocity_decay/>
        <self_collide>0</self_collide>
        <kinematic>0</kinematic>
      </link>
      <joint name='joint2' type='revolute'>
        <child>link2</child>
        <parent>link1</parent>
        <axis>
          <xyz>0.000204 1 -0.000204</xyz>
          <limit>
            <lower>-6.283</lower>
            <upper>6.283</upper>
            <effort>3460</effort>
            <velocity>2.094</velocity>
          </limit>
          <dynamics>
            <damping>0</damping>
            <friction>0</friction>
            <spring_reference>0</spring_reference>
            <spring_stiffness>0</spring_stiffness>
          </dynamics>
          <use_parent_model_frame>1</use_parent_model_frame>
        </axis>
      </joint>
      <link name='link3'>
        <pose frame=''>0 0.006284 0.5635 -1.571 0.000204 -0.000204</pose>
        <inertial>
          <pose frame=''>6e-06 0.07917 0.781807 0 -0 0</pose>
          <mass>3.614</mass>
          <inertia>
            <ixx>0.012</ixx>
            <ixy>-4.38e-06</ixy>
            <ixz>-1.2e-06</ixz>
            <iyy>0.008</iyy>
            <iyz>0.002</iyz>
            <izz>0.011</izz>
          </inertia>
        </inertial>
        <visual name='link3_visual'>
          <pose frame=''>0 0 0 0 -0 0</pose>
          <geometry>
            <mesh>
              <scale>1 1 1</scale>
              <uri>/home/dra/catkin_ws/src/doosan_robot_v003/dr_description/meshes/m0609/MF0609_3_0.stl</uri>
            </mesh>
          </geometry>
          <material>
            <script>
              <name>Gazebo/White</name>
              <uri>file://media/materials/scripts/gazebo.material</uri>
            </script>
          </material>
        </visual>
        <gravity>1</gravity>
        <velocity_decay/>
        <self_collide>0</self_collide>
        <kinematic>0</kinematic>
      </link>
      <joint name='joint3' type='revolute'>
        <child>link3</child>
        <parent>link2</parent>
        <axis>
          <xyz>0.000204 1 -0.000204</xyz>
          <limit>
            <lower>-2.793</lower>
            <upper>2.793</upper>
            <effort>1630</effort>
            <velocity>3.142</velocity>
          </limit>
          <dynamics>
            <damping>0</damping>
            <friction>0</friction>
            <spring_reference>0</spring_reference>
            <spring_stiffness>0</spring_stiffness>
          </dynamics>
          <use_parent_model_frame>1</use_parent_model_frame>
        </axis>
      </joint>
      <link name='link4'>
        <pose frame=''>7.5e-05 0.006359 0.9315 0 0.000204 -0.000204</pose>
        <inertial>
          <pose frame=''>-2.1e-05 0.12337 1.148 0 -0 0</pose>
          <mass>3.785</mass>
          <inertia>
            <ixx>0.177</ixx>
            <ixy>-2.34e-06</ixy>
            <ixz>-4.92e-06</ixz>
            <iyy>0.161</iyy>
            <iyz>-0.05</iyz>
            <izz>0.022</izz>
          </inertia>
        </inertial>
        <visual name='link4_visual'>
          <pose frame=''>0 0 0 0 -0 0</pose>
          <geometry>
            <mesh>
              <scale>1 1 1</scale>
              <uri>/home/dra/catkin_ws/src/doosan_robot_v003/dr_description/meshes/m0609/MF0609_4_0.stl</uri>
            </mesh>
          </geometry>
          <material>
            <script>
              <name>Gazebo/White</name>
              <uri>file://media/materials/scripts/gazebo.material</uri>
            </script>
          </material>
        </visual>
        <visual name='link4_visual_1'>
          <pose frame=''>0 0 0 0 -0 0</pose>
          <geometry>
            <mesh>
              <scale>1 1 1</scale>
              <uri>/home/dra/catkin_ws/src/doosan_robot_v003/dr_description/meshes/m0609/MF0609_4_1.stl</uri>
            </mesh>
          </geometry>
          <material>
            <script>
              <name>Gazebo/White</name>
              <uri>file://media/materials/scripts/gazebo.material</uri>
            </script>
          </material>
        </visual>
        <gravity>1</gravity>
        <velocity_decay/>
        <self_collide>0</self_collide>
        <kinematic>0</kinematic>
      </link>
      <joint name='joint4' type='revolute'>
        <child>link4</child>
        <parent>link3</parent>
        <axis>
          <xyz>0.000204 0 1</xyz>
          <limit>
            <lower>-6.283</lower>
            <upper>6.283</upper>
            <effort>50</effort>
            <velocity>3.927</velocity>
          </limit>
          <dynamics>
            <damping>0</damping>
            <friction>0</friction>
            <spring_reference>0</spring_reference>
            <spring_stiffness>0</spring_stiffness>
          </dynamics>
          <use_parent_model_frame>1</use_parent_model_frame>
        </axis>
      </joint>
      <link name='link5'>
        <pose frame=''>7.5e-05 0.006359 0.9315 -1.571 0.000204 -0.000204</pose>
        <inertial>
          <pose frame=''>-1.7e-05 0.06662 1.33103 0 -0 0</pose>
          <mass>2.598</mass>
          <inertia>
            <ixx>0.007</ixx>
            <ixy>-4.93e-06</ixy>
            <ixz>-5.57e-06</ixz>
            <iyy>0.004</iyy>
            <iyz>-6.64e-05</iyz>
            <izz>0.007</izz>
          </inertia>
        </inertial>
        <visual name='link5_visual'>
          <pose frame=''>0 0 0 0 -0 0</pose>
          <geometry>
            <mesh>
              <scale>1 1 1</scale>
              <uri>/home/dra/catkin_ws/src/doosan_robot_v003/dr_description/meshes/m0609/MF0609_5_0.stl</uri>
            </mesh>
          </geometry>
          <material>
            <script>
              <name>Gazebo/White</name>
              <uri>file://media/materials/scripts/gazebo.material</uri>
            </script>
          </material>
        </visual>
        <gravity>1</gravity>
        <velocity_decay/>
        <self_collide>0</self_collide>
        <kinematic>0</kinematic>
      </link>
      <joint name='joint5' type='revolute'>
        <child>link5</child>
        <parent>link4</parent>
        <axis>
          <xyz>0.000204 1 -0.000204</xyz>
          <limit>
            <lower>-6.283</lower>
            <upper>6.283</upper>
            <effort>50</effort>
            <velocity>3.927</velocity>
          </limit>
          <dynamics>
            <damping>0</damping>
            <friction>0</friction>
            <spring_reference>0</spring_reference>
            <spring_stiffness>0</spring_stiffness>
          </dynamics>
          <use_parent_model_frame>1</use_parent_model_frame>
        </axis>
      </joint>
      <link name='link6'>
        <pose frame=''>0.0001 0.006383 1.0525 0 0.000204 -0.000204</pose>
        <inertial>
          <pose frame=''>-0.000174 0.034708 1.40022 0 -0 0</pose>
          <mass>1.128</mass>
          <inertia>
            <ixx>0.001</ixx>
            <ixy>-2.79e-06</ixy>
            <ixz>5.78e-06</ixz>
            <iyy>0.001</iyy>
            <iyz>-6.67e-06</iyz>
            <izz>0.001</izz>
          </inertia>
        </inertial>
        <visual name='link6_visual'>
          <pose frame=''>0 0 0 0 -0 0</pose>
          <geometry>
            <mesh>
              <scale>1 1 1</scale>
              <uri>/home/dra/catkin_ws/src/doosan_robot_v003/dr_description/meshes/m0609/MF0609_6_0.stl</uri>
            </mesh>
          </geometry>
          <material>
            <script>
              <name>Gazebo/Grey</name>
              <uri>file://media/materials/scripts/gazebo.material</uri>
            </script>
          </material>
        </visual>
        <gravity>1</gravity>
        <velocity_decay/>
        <self_collide>0</self_collide>
        <kinematic>0</kinematic>
      </link>
      <joint name='joint6' type='revolute'>
        <child>link6</child>
        <parent>link5</parent>
        <axis>
          <xyz>0.000204 0 1</xyz>
          <limit>
            <lower>-6.283</lower>
            <upper>6.283</upper>
            <effort>50</effort>
            <velocity>3.927</velocity>
          </limit>
          <dynamics>
            <damping>0</damping>
            <friction>0</friction>
            <spring_reference>0</spring_reference>
            <spring_stiffness>0</spring_stiffness>
          </dynamics>
          <use_parent_model_frame>1</use_parent_model_frame>
        </axis>
      </joint>
      <static>0</static>
      <plugin name='gazebo_ros_control' filename='libgazebo_ros_control.so'>
        <robotNamespace>/doosan_robot</robotNamespace>
        <controlPeriod>0.001</controlPeriod>
        <robotSimType>gazebo_ros_control/DefaultRobotHWSim</robotSimType>
      </plugin>
      <pose frame=''>0 0 0 0 -0 0</pose>
    </model>
    <model name='car_008'>
      <pose frame=''>-2.33416 1.32918 0 0 -0 1.57</pose>
      <static>1</static>
      <link name='link'>
        <inertial>
          <mass>1</mass>
          <inertia>
            <ixx>0.083</ixx>
            <ixy>0</ixy>
            <ixz>0</ixz>
            <iyy>0.083</iyy>
            <iyz>0</iyz>
            <izz>0.083</izz>
          </inertia>
        </inertial>
        <collision name='collision'>
          <geometry>
            <box>
              <size>1 1 1</size>
            </box>
          </geometry>
          <max_contacts>10</max_contacts>
          <surface>
            <contact>
              <ode/>
            </contact>
            <bounce/>
            <friction>
              <torsional>
                <ode/>
              </torsional>
              <ode/>
            </friction>
          </surface>
        </collision>
        <visual name='visual'>
          <cast_shadows>0</cast_shadows>
          <geometry>
            <mesh>
              <uri>model://car_008/meshes/car_008.dae</uri>
              <scale>1 1 1</scale>
            </mesh>
          </geometry>
        </visual>
        <self_collide>0</self_collide>
        <kinematic>0</kinematic>
        <gravity>1</gravity>
      </link>
    </model>
    <state world_name='default'>
      <sim_time>0 0</sim_time>
      <real_time>0 0</real_time>
      <wall_time>1543322811 742516985</wall_time>
      <iterations>0</iterations>
      <model name='car_008'>
        <pose frame=''>-0.248262 -3.31405 0 0 -0 1.57</pose>
        <scale>1 1 1</scale>
        <link name='link'>
          <pose frame=''>-0.248262 -3.31405 0 0 -0 1.57</pose>
          <velocity>0 0 0 0 -0 0</velocity>
          <acceleration>0 0 0 0 -0 0</acceleration>
          <wrench>0 0 0 0 -0 0</wrench>
        </link>
      </model>
      <model name='ground_plane'>
        <pose frame=''>0 0 0 0 -0 0</pose>
        <scale>1 1 1</scale>
        <link name='link'>
          <pose frame=''>0 0 0 0 -0 0</pose>
          <velocity>0 0 0 0 -0 0</velocity>
          <acceleration>0 0 0 0 -0 0</acceleration>
          <wrench>0 0 0 0 -0 0</wrench>
        </link>
      </model>
      <model name='m0609'>
        <pose frame=''>-0.151023 -3.30336 1.40251 0 -0 0</pose>
        <scale>1 1 1</scale>
        <link name='base_0'>
          <pose frame=''>-0.151023 -3.30336 1.40251 0 -0 0</pose>
          <velocity>0 0 0 0 -0 0</velocity>
          <acceleration>0 0 0 0 -0 0</acceleration>
          <wrench>0 0 0 0 -0 0</wrench>
        </link>
        <link name='link1'>
          <pose frame=''>-0.151023 -3.30336 1.55501 0 -0 0</pose>
          <velocity>0 0 0 0 -0 0</velocity>
          <acceleration>0 0 0 0 -0 0</acceleration>
          <wrench>0 0 0 0 -0 0</wrench>
        </link>
        <link name='link2'>
          <pose frame=''>-0.151023 -3.29716 1.55501 3.14159 -1.57059 1.57059</pose>
          <velocity>0 0 0 0 -0 0</velocity>
          <acceleration>0 0 0 0 -0 0</acceleration>
          <wrench>0 0 0 0 -0 0</wrench>
        </link>
        <link name='link3'>
          <pose frame=''>-0.151023 -3.29707 1.96601 -1.571 0.000204 -0.000204</pose>
          <velocity>0 0 0 0 -0 0</velocity>
          <acceleration>0 0 0 0 -0 0</acceleration>
          <wrench>0 0 0 0 -0 0</wrench>
        </link>
        <link name='link4'>
          <pose frame=''>-0.150948 -3.297 2.33401 0 0.000204 -0.000204</pose>
          <velocity>0 0 0 0 -0 0</velocity>
          <acceleration>0 0 0 0 -0 0</acceleration>
          <wrench>0 0 0 0 -0 0</wrench>
        </link>
        <link name='link5'>
          <pose frame=''>-0.150948 -3.297 2.33401 -1.571 0.000204 -0.000204</pose>
          <velocity>0 0 0 0 -0 0</velocity>
          <acceleration>0 0 0 0 -0 0</acceleration>
          <wrench>0 0 0 0 -0 0</wrench>
        </link>
        <link name='link6'>
          <pose frame=''>-0.150923 -3.29698 2.45501 0 0.000204 -0.000204</pose>
          <velocity>0 0 0 0 -0 0</velocity>
          <acceleration>0 0 0 0 -0 0</acceleration>
          <wrench>0 0 0 0 -0 0</wrench>
        </link>
      </model>
      <light name='sun'>
        <pose frame=''>0 0 10 0 -0 0</pose>
      </light>
    </state>
  </world>
</sdf>
